<robot name="6dof_robot">
  <link name="base_link">
    <visual>
      <geometry>
        <cylinder length="0.02" radius="0.03"/>
        <origin xyz="0 0 0" rpy="0 0 0"/>
      </geometry>
    </visual>
    </link>
  <link name="link1">
      <visual>
      <geometry>
        <cylinder length="0.12" radius="0.03"/>
        <origin xyz="0 0 0" rpy="0 0 0"/>
      </geometry>
    </visual>
        </link>
  <link name="link2">
    <visual>
      <geometry>
        <cylinder length="0.25" radius="0.03"/>
        <origin xyz="0 0 0" rpy="0 0 0"/>
      </geometry>
    </visual>
  </link>
  <link name="link3">
    <visual>
      <geometry>
        <cylinder length="0.052" radius="0.03"/>
        <origin xyz="0 0 0" rpy="0 0 0"/>
      </geometry>
    </visual>
  </link>
  <link name="link4">
    <visual>
      <geometry>
        <cylinder length="0.09" radius="0.03"/>
        <origin xyz="0 0 0" rpy="0 0 0"/>
      </geometry>
    </visual>
  </link>
  <link name="link5">
        <visual>
      <geometry>
        <cylinder length="0.084" radius="0.03"/>
        <origin xyz="0 0 0" rpy="0 0 0"/>
      </geometry>
    </visual>
  </link>
  <link name="link6">
            <visual>
      <geometry>
        <cylinder length="0.08" radius="0.03"/>
        <origin xyz="0 0 0" rpy="0 0 0"/>
      </geometry>
    </visual>
  </link>
  <joint name="rotary_base" type="continuous">
    <parent link="base_link"/>
    <child link="link1"/>
    <origin xyz="0 0 0.02" rpy="0 0 0" />
    <axis xyz="0 0 1" />
  </joint>
  <joint name="joint1" type="continuous">
    <parent link="link1"/>
    <child link="link2"/>
    <origin xyz="0 0 0.12" rpy="-1.57 0 0" />
    <axis xyz="0 0 1" />
  </joint>

  <joint name="joint2" type="continuous">
    <parent link="link2"/>
    <child link="link3"/>
    <origin xyz="0 -0.225 0" rpy="0 0 -1.57" />
    <axis xyz="0 0 1" />
  </joint>

  <joint name="joint3" type="continuous">
    <parent link="link3"/>
    <child link="link4"/>
    <origin xyz="0 0 0.052" rpy="1.57 0 0" />
    <axis xyz="0 0 1" />
  </joint>
  <joint name="joint4" type="continuous">
    <parent link="link4"/>
    <child link="link5"/>
    <origin xyz="0 0 -0.09" rpy="-1.57 0 0" />
    <axis xyz="0 0 1" />
  </joint>
  <joint name="gripper" type="continuous">
    <parent link="link5"/>
    <child link="link6"/>
    <origin xyz="0 0.084 0" rpy="1.57 0 0" />
    <axis xyz="0 0 1" />
  </joint>
</robot>
